<?xml version="1.0" encoding="utf-8" ?>
<!-- This URDF was automatically created by SolidWorks to URDF Exporter! Originally created by Stephen Brawner (brawner@gmail.com) 
     Commit Version: 1.5.1-0-g916b5db  Build Version: 1.5.7152.31018
     For more information, please see http://wiki.ros.org/sw_urdf_exporter -->
<robot name="robot">
    <link name="map">
    </link>
    <link name="optical">
    </link>
    <link name="base_link_Chasis">
        <inertial>
        <origin
            xyz="-0.0176250593499407 0.000487296918118385 0.0603462602324048"
            rpy="0 0 0" />
        <mass
            value="5.1498884920758" />
        <inertia
            ixx="0.0269958762265313"
            ixy="1.6509880552203E-05"
            ixz="-6.87240827549635E-07"
            iyy="0.0269179615683537"
            iyz="5.19119383098109E-08"
            izz="0.0513021127607407" />
        </inertial>

        <visual>
            <origin xyz="0 0 0" rpy="0 0 0" />
            <geometry>
                <mesh filename="package://Ensamble_URDF_2ndT/meshes/base_link_Chasis.STL" />
            </geometry>
            <material name="">
                <color rgba="0.752941176470588 0.752941176470588 0.752941176470588 1" />
            </material>
        </visual>
        <collision>
            <origin xyz="0 0 0" rpy="0 0 0" />
            <geometry>
                <mesh filename="package://Ensamble_URDF_2ndT/meshes/base_link_Chasis.STL" />
            </geometry>
        </collision>
    </link>
    <link name="rear_right_wheel">
        
        <inertial>
        <origin
            xyz="5.67991412472879E-07 -2.82678237514822E-06 -0.0308169422322422"
            rpy="0 0 0" />
        <mass
            value="0.622419475189312" />
        <inertia
            ixx="0.00062490705708195"
            ixy="3.27878592513705E-09"
            ixz="-4.02329981568964E-11"
            iyy="0.000624902314874054"
            iyz="-5.1108057156914E-09"
            izz="0.00114905854450842" />
        </inertial>
        <visual>
            <origin xyz="0 0 0" rpy="0 0 0" />
            <geometry>
                <mesh filename="package://Ensamble_URDF_2ndT/meshes/Link_1_1_wheel.STL" />
            </geometry>
            <material name="">
                <color rgba="0.0752941176470588 0.0752941176470588 0.0752941176470588 1" />
            </material>
        </visual>
        <collision>
            <origin xyz="0 0 0" rpy="0 0 0" />
            <geometry>
                <mesh filename="package://Ensamble_URDF_2ndT/meshes/Link_1_1_wheel.STL" />
            </geometry>
        </collision>
    </link>
    <joint name="dummy_joint" type="fixed">
        <parent link="map" />
        <child link="base_link_Chasis" />
    </joint>
  <joint
    name="joint_rear_right"
    type="continuous">
    <origin
      xyz="-0.12 -0.19478 0.0195"
      rpy="1.5708 0 0" />
    <parent
      link="base_link_Chasis" />
    <child
      link="rear_right_wheel" />
    <axis
      xyz="0 0 -1" />
    <!--<limit effort="10000" velocity="1000"/>-->
    <joint_properties damping="0.7"/>
  </joint>
    <link name="rear_left_wheel">
        
        <inertial>
        <origin
            xyz="2.7380927147963E-06 -9.03416358916109E-07 -0.0321210915173869"
            rpy="0 0 0" />
        <mass
            value="0.622419475189309" />
        <inertia
            ixx="0.00062490065579211"
            ixy="3.60794637909731E-10"
            ixz="4.42299708576457E-09"
            iyy="0.000624908716163889"
            iyz="-2.5610643382685E-09"
            izz="0.00114905854450842" />
        </inertial>

        <visual>
            <origin xyz="0 0 0" rpy="0 0 0" />
            <geometry>
                <mesh filename="package://Ensamble_URDF_2ndT/meshes/Link_1_2_wheel.STL" />
            </geometry>
            <material name="">
                <color rgba="0.0752941176470588 0.0752941176470588 0.0752941176470588 1" />
            </material>
        </visual>
        <collision>
            <origin xyz="0 0 0" rpy="0 0 0" />
            <geometry>
                <mesh filename="package://Ensamble_URDF_2ndT/meshes/Link_1_2_wheel.STL" />
            </geometry>
        </collision>
    </link>
  <joint
    name="joint_rear_left"
    type="continuous">
    <origin
      xyz="-0.12 0.19608 0.0195"
      rpy="-1.5708 0 0" />
    <parent
      link="base_link_Chasis" />
    <child
      link="rear_left_wheel" />
    <axis
      xyz="0 0 1" />
    <!--<limit effort="10000" velocity="1000"/>-->
    <joint_properties damping="0.7"/>
  </joint>
    <link name="front_right_wheel">
        
        <inertial>
        <origin
            xyz="2.45343850319157E-06 -1.51457992347837E-06 -0.0308169422322417"
            rpy="0 0 0" />
        <mass
            value="0.622419475189309" />
        <inertia
            ixx="0.000624901253478588"
            ixy="2.14254962065621E-09"
            ixz="3.7073277047334E-09"
            iyy="0.00062490811847741"
            iyz="-3.51819202576334E-09"
            izz="0.00114905854450842" />
        </inertial>

        <visual>
            <origin xyz="0 0 0" rpy="0 0 0" />
            <geometry>
                <mesh filename="package://Ensamble_URDF_2ndT/meshes/Link_1_3_wheel.STL" />
            </geometry>
            <material name="">
                <color rgba="0.0752941176470588 0.0752941176470588 0.0752941176470588 1" />
            </material>
        </visual>
        <collision>
            <origin xyz="0 0 0" rpy="0 0 0" />
            <geometry>
                <mesh filename="package://Ensamble_URDF_2ndT/meshes/Link_1_3_wheel.STL" />
            </geometry>
        </collision>
    </link>
  <joint
    name="joint_front_right"
    type="continuous">
    <origin
      xyz="0.08 -0.19478 0.0195"
      rpy="1.5708 0 0" />
    <parent
      link="base_link_Chasis" />
    <child
      link="front_right_wheel" />
    <axis
      xyz="0 0 -1" />
    <!--<limit effort="10000" velocity="1000"/>-->
    <joint_properties damping="0.7"/>
  </joint>
    <link name="front_left_wheel">
        
        <inertial>
        <origin
            xyz="6.88887376976144E-07 2.79977624487171E-06 -0.0321210915173852"
            rpy="0 0 0" />
        <mass
            value="0.622419475189309" />
        <inertia
            ixx="0.000624908723580364"
            ixy="2.65213544825715E-10"
            ixz="2.21122175396398E-09"
            iyy="0.000624900648375636"
            iyz="4.60786850214148E-09"
            izz="0.00114905854450842" />
        </inertial>

        <visual>
            <origin xyz="0 0 0" rpy="0 0 0" />
            <geometry>
                <mesh filename="package://Ensamble_URDF_2ndT/meshes/Link_1_4_wheel.STL" />
            </geometry>
            <material name="">
                <color rgba="0.0752941176470588 0.0752941176470588 0.0752941176470588 1" />
            </material>
        </visual>
        <collision>
            <origin xyz="0 0 0" rpy="0 0 0" />
            <geometry>
                <mesh filename="package://Ensamble_URDF_2ndT/meshes/Link_1_4_wheel.STL" />
            </geometry>
        </collision>
    </link>
  <joint
    name="joint_front_left"
    type="continuous">
    <origin
      xyz="0.08 0.19608 0.0195"
      rpy="-1.5708 0 0" />
    <parent
      link="base_link_Chasis" />
    <child
      link="front_left_wheel" />
    <axis
      xyz="0 0 1" />
    <!--<limit effort="10000" velocity="1000"/>-->
    <joint_properties damping="0.7"/>
  </joint>
    <link name="Link_2_Arm">
        
        <inertial>
            <origin xyz="0.00748196672374324 0.00102802561169185 0.0638410985827166" rpy="0 0 0" />
            <mass value="0.628890750175801" />
            <inertia ixx="0.000520538685244632" ixy="-2.12235972486672E-06" ixz="-0.000139357039232038" iyy="0.000728419435655154" iyz="-1.13027487326274E-06" izz="0.000770486257960158" />
        </inertial>

        <visual>
            <origin xyz="0 0 0" rpy="0 0 0" />
            <geometry>
                <mesh filename="package://Ensamble_URDF_2ndT/meshes/Link_2_Arm.STL" />
            </geometry>
            <material name="">
                <color rgba="0.752941176470588 0.752941176470588 0.752941176470588 1" />
            </material>
        </visual>
        <collision>
            <origin xyz="0 0 0" rpy="0 0 0" />
            <geometry>
                <mesh filename="package://Ensamble_URDF_2ndT/meshes/Link_2_Arm.STL" />
            </geometry>
        </collision>
    </link>
    <joint name="joint_2_Arm" type="revolute">
        <origin xyz="0 0 0.098503" rpy="0 0 0" />
        <parent link="base_link_Chasis" />
        <child link="Link_2_Arm" />
        <axis xyz="0 0 1" />
        <dynamics damping="0.1" friction="0.0" />
        <limit lower="-3.14" upper="3.14" effort="100" velocity="100" />
    </joint>
    <link name="Link_3_Arm">
        
        <inertial>
            <origin xyz="0.0296690817173591 0.0937475303009118 0.0154851256686125" rpy="0 0 0" />
            <mass value="0.253359108687758" />
            <inertia ixx="0.00110683077017184" ixy="-0.000324885669810858" ixz="1.02859280609467E-07" iyy="0.000181665186280893" iyz="3.25419397857424E-07" izz="0.0012795061824751" />
        </inertial>

        <visual>
            <origin xyz="0 0 0" rpy="0 0 0" />
            <geometry>
                <mesh filename="package://Ensamble_URDF_2ndT/meshes/Link_3_Arm.STL" />
            </geometry>
            <material name="">
                <color rgba="0.752941176470588 0.752941176470588 0.752941176470588 1" />
            </material>
        </visual>
        <collision>
            <origin xyz="0 0 0" rpy="0 0 0" />
            <geometry>
                <mesh filename="package://Ensamble_URDF_2ndT/meshes/Link_3_Arm.STL" />
            </geometry>
        </collision>
    </link>
    <joint name="joint_3_Arm" type="revolute">
        <origin xyz="0.063383 0.0021739 0.12369" rpy="1.5708 0 0" />
        <parent link="Link_2_Arm" />
        <child link="Link_3_Arm" />
        <axis xyz="0.034278 0 0.99941" />
        <dynamics damping="0.1" friction="0.0" />
        <limit lower="-0.6" upper="1.4" effort="100" velocity="100" />
    </joint>
    <link name="Link_4_Arm">
        
        <inertial>
            <origin xyz="0.12214 -0.0031288 -0.025262" rpy="0 0 0" />
            <mass value="0.5315" />
            <inertia ixx="0.00053038" ixy="3.203E-05" ixz="3.3052E-05" iyy="0.0012792" iyz="8.2845E-06" izz="0.0010824" />
        </inertial>

        <visual>
            <origin xyz="0 0 0" rpy="0 0 0" />
            <geometry>
                <mesh filename="package://Ensamble_URDF_2ndT/meshes/Link_4_Arm.STL" />
            </geometry>
            <material name="">
                <color rgba="0.75294 0.75294 0.75294 1" />
            </material>
        </visual>
        <collision>
            <origin xyz="0 0 0" rpy="0 0 0" />
            <geometry>
                <mesh filename="package://Ensamble_URDF_2ndT/meshes/Link_4_Arm.STL" />
            </geometry>
        </collision>
    </link>
    <joint name="joint_4_Arm" type="revolute">
        <origin xyz="0.060241 0.1907 -0.0020662" rpy="0 0 0" />
        <parent link="Link_3_Arm" />
        <child link="Link_4_Arm" />
        <axis xyz="-0.034278 0 -0.99941" />
        <dynamics damping="0.1" friction="0.0" />
        <limit lower="-1.57" upper="1.2" effort="100" velocity="100" />
    </joint>
    <link name="Link_5_Arm">
        
        <inertial>
            <origin xyz="0.10453 -0.026221 -0.022979" rpy="0 0 0" />
            <mass value="0.34582" />
            <inertia ixx="0.00011962" ixy="0.00014937" ixz="1.8439E-11" iyy="0.00069107" iyz="-7.1519E-10" izz="0.0007295" />
        </inertial>

        <visual>
            <origin xyz="0 0 0" rpy="0 0 0" />
            <geometry>
                <mesh filename="package://Ensamble_URDF_2ndT/meshes/Link_5_Arm.STL" />
            </geometry>
            <material name="">
                <color rgba="1 1 1 1" />
            </material>
        </visual>
        <collision>
            <origin xyz="0 0 0" rpy="0 0 0" />
            <geometry>
                <mesh filename="package://Ensamble_URDF_2ndT/meshes/Link_5_Arm.STL" />
            </geometry>
        </collision>
    </link>
    <joint name="joint_5_Arm" type="revolute">
        <origin xyz="0.21278 -0.0095961 -0.0037813" rpy="0 0 0" />
        <parent link="Link_4_Arm" />
        <child link="Link_5_Arm" />
        <axis xyz="-0.034278 0 -0.99941" />
        <dynamics damping="0.1" friction="0.01" />
        <limit lower="-2.8" upper="2.8" effort="100" velocity="100" />
    </joint>

  <link name="rgbd_cam">
    <inertial>
      <origin xyz="0.221 0.0 0.045" rpy="0.0 0.0 0.0"/>
      <mass value="0.1"/>
      <inertia ixx="0.0" ixy="0.0" ixz="0.0" iyy="0.0" iyz="0.0" izz="0.0"/>
    </inertial>
    <visual>
      <origin xyz="0.0 0.0 0.0" rpy="0.0 0.0 0.0"/>
      <geometry>
        <box size="0.01 0.01 0.01"/>
      </geometry>
    </visual>
  </link>

  <joint name="rgbd_link" type="fixed">
    <parent link="base_link_Chasis"/>
    <child link="rgbd_cam"/>
    <origin xyz="0.221 0.0 0.045" rpy="0.0 0.0 0.0"/>
  </joint>
  <joint name="optical_joint" type="fixed">
    <parent link="rgbd_cam"/>
    <child link="optical"/>
    <origin xyz="0.0 0.0 0.0" rpy="-1.5708 0.0 -1.5708"/>   
  </joint>
    

  <transmission name="transmission_rear_right">
    <type>transmission_interface/SimpleTransmission</type>
    <actuator name="motor_rear_right">
      <hardwareInterface>hardware_interface/EffortJointInterface</hardwareInterface>
      <mechanicalReduction>75</mechanicalReduction>
    </actuator>
    <joint name="joint_rear_right">
      <hardwareInterface>hardware_interface/VelocityJointInterface</hardwareInterface>
    </joint>
  </transmission>
  <transmission name="transmission_rear_left">
    <type>transmission_interface/SimpleTransmission</type>
    <actuator name="motor_rear_left">
      <hardwareInterface>hardware_interface/EffortJointInterface</hardwareInterface>
      <mechanicalReduction>75</mechanicalReduction>
    </actuator>
    <joint name="joint_rear_left">
      <hardwareInterface>hardware_interface/VelocityJointInterface</hardwareInterface>
    </joint>
  </transmission>
  <transmission name="transmission_front_right">
    <type>transmission_interface/SimpleTransmission</type>
    <actuator name="motor_front_right">
      <hardwareInterface>hardware_interface/EffortJointInterface</hardwareInterface>
      <mechanicalReduction>75</mechanicalReduction>
    </actuator>
    <joint name="joint_front_right">
      <hardwareInterface>hardware_interface/VelocityJointInterface</hardwareInterface>
    </joint>
  </transmission>
  <transmission name="transmission_front_left">
    <type>transmission_interface/SimpleTransmission</type>
    <actuator name="motor_front_left">
      <hardwareInterface>hardware_interface/EffortJointInterface</hardwareInterface>
      <mechanicalReduction>75</mechanicalReduction>
    </actuator>
    <joint name="joint_front_left">
      <hardwareInterface>hardware_interface/VelocityJointInterface</hardwareInterface>
    </joint>
  </transmission>
    <transmission name="trans_joint_2_Arm">
        <type>transmission_interface/SimpleTransmission</type>
        <joint name="joint_2_Arm">
            <hardwareInterface>hardware_interface/EffortJointInterface</hardwareInterface>
        </joint>
        <actuator name="joint_2_Arm_motor">
            <hardwareInterface>hardware_interface/EffortJointInterface</hardwareInterface>
            <mechanicalReduction>1</mechanicalReduction>
        </actuator>
    </transmission>
    <transmission name="trans_joint_3_Arm">
        <type>transmission_interface/SimpleTransmission</type>
        <joint name="joint_3_Arm">
            <hardwareInterface>hardware_interface/EffortJointInterface</hardwareInterface>
        </joint>
        <actuator name="joint_3_Arm_motor">
            <hardwareInterface>hardware_interface/EffortJointInterface</hardwareInterface>
            <mechanicalReduction>1</mechanicalReduction>
        </actuator>
    </transmission>
    <transmission name="trans_joint_4_Arm">
        <type>transmission_interface/SimpleTransmission</type>
        <joint name="joint_4_Arm">
            <hardwareInterface>hardware_interface/EffortJointInterface</hardwareInterface>
        </joint>
        <actuator name="joint_4_Arm_motor">
            <hardwareInterface>hardware_interface/EffortJointInterface</hardwareInterface>
            <mechanicalReduction>1</mechanicalReduction>
        </actuator>
    </transmission>
    <transmission name="trans_joint_5_Arm">
        <type>transmission_interface/SimpleTransmission</type>
        <joint name="joint_5_Arm">
            <hardwareInterface>hardware_interface/EffortJointInterface</hardwareInterface>
        </joint>
        <actuator name="joint_5_Arm_motor">
            <hardwareInterface>hardware_interface/EffortJointInterface</hardwareInterface>
            <mechanicalReduction>1</mechanicalReduction>
        </actuator>
    </transmission>

  <gazebo reference="base_link_Chasis">
    <material>Gazebo/Orange</material>
  </gazebo>
  <gazebo reference="rear_right_wheel">
    <material>Gazebo/Black</material>
  </gazebo>
  <gazebo reference="rear_left_wheel">
    <material>Gazebo/Black</material>
  </gazebo>
  <gazebo reference="front_right_wheel">
    <material>Gazebo/Black</material>
  </gazebo>
  <gazebo reference="front_left_wheel">
    <material>Gazebo/Black</material>
  </gazebo>
  <gazebo reference="rgbd_cam">
    <material>Gazebo/Red</material>
  </gazebo>

  <gazebo>
    <plugin name="gazebo_ros_control" filename="libgazebo_ros_control.so">
      <robotNamespace>/robot</robotNamespace>
      <robotSimType>gazebo_ros_control/DefaultRobotHWSim</robotSimType>
    </plugin>
  </gazebo>

  <gazebo reference="rgbd_cam">
    <sensor type="depth" name="camera">  
      <pose>0.0 0.0 0.0 1.0 0.0 0.0</pose>     
      <always_on>true</always_on>
      <visualize>true</visualize>             
      <camera>
          <horizontal_fov>1.047</horizontal_fov>
          <image>
              <width>640</width>
              <height>480</height>
              <format>R8G8B8</format>
          </image>
          <depth_camera>
          </depth_camera>
          <clip>
              <near>0.1</near>
              <far>3</far>
          </clip>
      </camera>
      <plugin name="camera_controller" filename="libgazebo_ros_openni_kinect.so">
          <baseline>0.2</baseline>
          <alwaysOn>true</alwaysOn>
              <updateRate>10.0</updateRate>
              <cameraName>camera</cameraName>
              <frameName>optical</frameName>                   
          <imageTopicName>rgb/image_raw</imageTopicName>
          <depthImageTopicName>depth/image_raw</depthImageTopicName>
          <pointCloudTopicName>depth/points</pointCloudTopicName>
          <cameraInfoTopicName>rgb/camera_info</cameraInfoTopicName>              
          <depthImageCameraInfoTopicName>depth/camera_info</depthImageCameraInfoTopicName>            
          <pointCloudCutoff>0.4</pointCloudCutoff>                
              <hackBaseline>0.07</hackBaseline>
              <distortionK1>0.0</distortionK1>
              <distortionK2>0.0</distortionK2>
              <distortionK3>0.0</distortionK3>
              <distortionT1>0.0</distortionT1>
              <distortionT2>0.0</distortionT2>
          <CxPrime>0.0</CxPrime>
          <Cx>0.0</Cx>
          <Cy>0.0</Cy>
          <Or>0.0</Or>
          <Op>1.5708</Op>
          <Oy>0.0</Oy>
          <focalLength>0.0</focalLength>
          </plugin>
    </sensor>
  </gazebo>
</robot>